Workbook

Sheet table
B1: S | C1: E | D1: 0 | E1: 1 | F1: a | G1: d | H1: b
A2: qa | B2: qa,S,+1 | C2: qa,qN,-1 | D2: qe,0,+1 | E2: qe,1,+1 | F2: qb,a,+1 | G2: qN,a,+1 | H2: qN,a,-1
A3: qb | B3: qN,S,-1 | C3: qN,E,-1 | D3: qN,b,-1 | E3: qN,b,-1 | F3: qN,b,-1 | G3: qc,d,+1 | H3: qN,b,-1
A4: qc | B4: qN,S,-1 | C4: qN,E,-1 | D4: qN,b,-1 | E4: qN,b,-1 | F4: qN,b,-1 | G4: qd,d,+1 | H4: qN,b,-1
A5: qd | B5: qN,S,-1 | C5: qY,E,-1 | D5: qd,0,+1 | E5: qd,1,+1 | F5: qN,b,-1 | G5: qN,d,+1 | H5: qY,b,-1
A6: qe | B6: qN,S,-1 | C6: qN,E,-1 | D6: qe,0,+1 | E6: qe,1,+1 | F6: qf,a,+1 | G6: qN,d,+1 | H6: qN,b,-1
A7: qf | B7: qN,S,-1 | C7: qN,E,-1 | D7: qN,b,-1 | E7: qN,b,-1 | F7: qN,b,-1 | G7: qg,d,+1 | H7: qN,b,-1
A8: qg | B8: qN,S,-1 | C8: qN,E,-1 | D8: qN,b,-1 | E8: qN,b,-1 | F8: qN,b,-1 | G8: qh,d,+1 | H8: qN,b,-1
A9: qh | B9: qN,S,-1 | C9: qY,E,-1 | D9: q00,0,-1 | E9: q00,1,-1 | F9: qN,b,-1 | G9: qN,d,+1 | H9: qN,b,-1
A10: q00 | B10: q01,S,+1 | C10: qN,E,-1 | D10: q00,0,-1 | E10: q00,1,-1 | F10: q00,a,-1 | G10: q00,d,-1 | H10: q00,b,-1
A11: q01 | B11: qN,S,+1 | C11: qz2a,E,-1 | D11: q01,0,+1 | E11: q01,1,+1 | F11: q01,a,+1 | G11: q01,d,+1 | H11: qz2a,b,-1
A12: qz2a | B12: qN,S,+1 | C12: qz2a,E,-1 | D12: qz2a,0,-1 | E12: q0,1,+1 | F12: qN,a,-1 | G12: qY,d,-1 | H12: qN,b,-1
A13: q0 | B13: q0,S,1 | C13: q1,E,-1 | D13: q0,0,1 | E13: q0,1,1 | F13: q0,a,1 | G13: q0,d,1 | H13: q1,b,-1
... A17: q4 | B17: q01,S,+1 | C17: qN,E,+1 | D17: q4,0,-1 | E17: q4,1,-1 | F17: qN,a,-1 | G17: qN,d,-1 | H17: qN,b,-1

Sheet BinaryAddition
A1: state | B1: symbol | C1: nstate | D1: nsymbol | E1: move
A2: qa | B2: S | C2: {=INDIRECT("table!R"&(MATCH(A2,table!$A$2:$A$17)+1)&"C"&(MATCH(BinaryAddition!B2,table!$B$1:$H$1,0)+1),FALSE)} -> qa,S,+1 | D2: S | E2: 1
A3: qb | B3: S | C3: {=INDIRECT("table!R"&(MATCH(A3,table!$A$2:$A$17)+1)&"C"&(MATCH(BinaryAddition!B3,table!$B$1:$H$1,0)+1),FALSE)} -> qN,S,-1 | D3: S | E3: -1
A4: qc | B4: S | C4: {=INDIRECT("table!R"&(MATCH(A4,table!$A$2:$A$17)+1)&"C"&(MATCH(BinaryAddition!B4,table!$B$1:$H$1,0)+1),FALSE)} -> qN,S,-1 | D4: S | E4: -1
A5: qd | B5: S | C5: {=INDIRECT("table!R"&(MATCH(A5,table!$A$2:$A$17)+1)&"C"&(MATCH(BinaryAddition!B5,table!$B$1:$H$1,0)+1),FALSE)} -> qN,S,-1 | D5: S | E5: -1
A6: qe | B6: S | C6: {=INDIRECT("table!R"&(MATCH(A6,table!$A$2:$A$17)+1)&"C"&(MATCH(BinaryAddition!B6,table!$B$1:$H$1,0)+1),FALSE)} -> qN,S,-1 | D6: S | E6: -1
A7: qf | B7: S | C7: {=INDIRECT("table!R"&(MATCH(A7,table!$A$2:$A$17)+1)&"C"&(MATCH(BinaryAddition!B7,table!$B$1:$H$1,0)+1),FALSE)} -> qN,S,-1 | D7: S | E7: -1
A8: qg | B8: S | C8: {=INDIRECT("table!R"&(MATCH(A8,table!$A$2:$A$17)+1)&"C"&(MATCH(BinaryAddition!B8,table!$B$1:$H$1,0)+1),FALSE)} -> qN,S,-1 | D8: S | E8: -1
A9: qh | B9: S | C9: {=INDIRECT("table!R"&(MATCH(A9,table!$A$2:$A$17)+1)&"C"&(MATCH(BinaryAddition!B9,table!$B$1:$H$1,0)+1),FALSE)} -> qN,S,-1 | D9: S | E9: -1
A10: q00 | B10: S | C10: {=INDIRECT("table!R"&(MATCH(A10,table!$A$2:$A$17)+1)&"C"&(MATCH(BinaryAddition!B10,table!$B$1:$H$1,0)+1),FALSE)} -> #N/A | D10: S | E10: 1
A11: q01 | B11: S | C11: {=INDIRECT("table!R"&(MATCH(A11,table!$A$2:$A$17)+1)&"C"&(MATCH(BinaryAddition!B11,table!$B$1:$H$1,0)+1),FALSE)} -> #N/A | D11: S | E11: 1
A12: qz2a | B12: S | C12: {=INDIRECT("table!R"&(MATCH(A12,table!$A$2:$A$17)+1)&"C"&(MATCH(BinaryAddition!B12,table!$B$1:$H$1,0)+1),FALSE)} -> q01,S,+1 | D12: S | E12: 1
A13: q0 | B13: S | C13: {=INDIRECT("table!R"&(MATCH(A13,table!$A$2:$A$17)+1)&"C"&(MATCH(BinaryAddition!B13,table!$B$1:$H$1,0)+1),FALSE)} -> #N/A | D13: S | E13: 1
... A15: q2 | B15: S | C15: {=INDIRECT("table!R"&(MATCH(A15,table!$A$2:$A$17)+1)&"C"&(MATCH(BinaryAddition!B15,table!$B$1:$H$1,0)+1),FALSE)} -> #N/A | D15: S | E15: 1
A16: q3 | B16: S | C16: {=INDIRECT("table!R"&(MATCH(A16,table!$A$2:$A$17)+1)&"C"&(MATCH(BinaryAddition!B16,table!$B$1:$H$1,0)+1),FALSE)} -> #N/A | D16: 1 | E16: 1
A17: q4 | B17: S | C17: {=INDIRECT("table!R"&(MATCH(A17,table!$A$2:$A$17)+1)&"C"&(MATCH(BinaryAddition!B17,table!$B$1:$H$1,0)+1),FALSE)} -> #N/A | D17: S | E17: 1
A18: qa | B18: E | C18: {=INDIRECT("table!R"&(MATCH(A18,table!$A$2:$A$17)+1)&"C"&(MATCH(BinaryAddition!B18,table!$B$1:$H$1,0)+1),FALSE)} -> qa,qN,-1 | D18: qN | E18: -1
A19: qb | B19: E | C19: {=INDIRECT("table!R"&(MATCH(A19,table!$A$2:$A$17)+1)&"C"&(MATCH(BinaryAddition!B19,table!$B$1:$H$1,0)+1),FALSE)} -> qN,E,-1 | D19: E | E19: -1
A20: qc | B20: E | C20: {=INDIRECT("table!R"&(MATCH(A20,table!$A$2:$A$17)+1)&"C"&(MATCH(BinaryAddition!B20,table!$B$1:$H$1,0)+1),FALSE)} -> qN,E,-1 | D20: E | E20: -1
A21: qd | B21: E | C21: {=INDIRECT("table!R"&(MATCH(A21,table!$A$2:$A$17)+1)&"C"&(MATCH(BinaryAddition!B21,table!$B$1:$H$1,0)+1),FALSE)} -> qY,E,-1 | D21: E | E21: -1
A22: qe | B22: E | C22: {=INDIRECT("table!R"&(MATCH(A22,table!$A$2:$A$17)+1)&"C"&(MATCH(BinaryAddition!B22,table!$B$1:$H$1,0)+1),FALSE)} -> qN,E,-1 | D22: E | E22: -1
A23: qf | B23: E | C23: {=INDIRECT("table!R"&(MATCH(A23,table!$A$2:$A$17)+1)&"C"&(MATCH(BinaryAddition!B23,table!$B$1:$H$1,0)+1),FALSE)} -> qN,E,-1 | D23: E | E23: -1
A24: qg | B24: E | C24: {=INDIRECT("table!R"&(MATCH(A24,table!$A$2:$A$17)+1)&"C"&(MATCH(BinaryAddition!B24,table!$B$1:$H$1,0)+1),FALSE)} -> qN,E,-1 | D24: E | E24: -1
A25: qh | B25: E | C25: {=INDIRECT("table!R"&(MATCH(A25,table!$A$2:$A$17)+1)&"C"&(MATCH(BinaryAddition!B25,table!$B$1:$H$1,0)+1),FALSE)} -> qY,E,-1 | D25: E | E25: -1
A26: q00 | B26: E | C26: {=INDIRECT("table!R"&(MATCH(A26,table!$A$2:$A$17)+1)&"C"&(MATCH(BinaryAddition!B26,table!$B$1:$H$1,0)+1),FALSE)} -> #N/A | D26: E | E26: -1
A27: q01 | B27: E | C27: {=INDIRECT("table!R"&(MATCH(A27,table!$A$2:$A$17)+1)&"C"&(MATCH(BinaryAddition!B27,table!$B$1:$H$1,0)+1),FALSE)} -> #N/A | D27: E | E27: -1
A28: qz2a | B28: E | C28: {=INDIRECT("table!R"&(MATCH(A28,table!$A$2:$A$17)+1)&"C"&(MATCH(BinaryAddition!B28,table!$B$1:$H$1,0)+1),FALSE)} -> qN,E,+1 | D28: E | E28: -1
... A33: q4 | B33: E | C33: {=INDIRECT("table!R"&(MATCH(A33,table!$A$2:$A$17)+1)&"C"&(MATCH(BinaryAddition!B33,table!$B$1:$H$1,0)+1),FALSE)} -> #N/A | D33: E | E33: 1
A34: qa | B34: 0 | C34: {=INDIRECT("table!R"&(MATCH(A34,table!$A$2:$A$17)+1)&"C"&(MATCH(BinaryAddition!B34,table!$B$1:$H$1,0)+1),FALSE)} -> qe,0,+1 | D34: 0 | E34: 1
A35: qb | B35: 0 | C35: {=INDIRECT("table!R"&(MATCH(A35,table!$A$2:$A$17)+1)&"C"&(MATCH(BinaryAddition!B35,table!$B$1:$H$1,0)+1),FALSE)} -> qN,b,-1 | D35: b | E35: -1
A36: qc | B36: 0 | C36: {=INDIRECT("table!R"&(MATCH(A36,table!$A$2:$A$17)+1)&"C"&(MATCH(BinaryAddition!B36,table!$B$1:$H$1,0)+1),FALSE)} -> qN,b,-1 | D36: b | E36: -1
A37: qd | B37: 0 | C37: {=INDIRECT("table!R"&(MATCH(A37,table!$A$2:$A$17)+1)&"C"&(MATCH(BinaryAddition!B37,table!$B$1:$H$1,0)+1),FALSE)} -> qd,0,+1 | D37: 0 | E37: 1
A38: qe | B38: 0 | C38: {=INDIRECT("table!R"&(MATCH(A38,table!$A$2:$A$17)+1)&"C"&(MATCH(BinaryAddition!B38,table!$B$1:$H$1,0)+1),FALSE)} -> qe,0,+1 | D38: 0 | E38: 1
A39: qf | B39: 0 | C39: {=INDIRECT("table!R"&(MATCH(A39,table!$A$2:$A$17)+1)&"C"&(MATCH(BinaryAddition!B39,table!$B$1:$H$1,0)+1),FALSE)} -> qN,b,-1 | D39: b | E39: -1
A40: qg | B40: 0 | C40: {=INDIRECT("table!R"&(MATCH(A40,table!$A$2:$A$17)+1)&"C"&(MATCH(BinaryAddition!B40,table!$B$1:$H$1,0)+1),FALSE)} -> qN,b,-1 | D40: b | E40: -1
A41: qh | B41: 0 | C41: {=INDIRECT("table!R"&(MATCH(A41,table!$A$2:$A$17)+1)&"C"&(MATCH(BinaryAddition!B41,table!$B$1:$H$1,0)+1),FALSE)} -> q00,0,-1 | D41: 0 | E41: -1
A42: q00 | B42: 0 | C42: {=INDIRECT("table!R"&(MATCH(A42,table!$A$2:$A$17)+1)&"C"&(MATCH(BinaryAddition!B42,table!$B$1:$H$1,0)+1),FALSE)} -> #N/A | D42: 0 | E42: -1
A43: q01 | B43: 0 | C43: {=INDIRECT("table!R"&(MATCH(A43,table!$A$2:$A$17)+1)&"C"&(MATCH(BinaryAddition!B43,table!$B$1:$H$1,0)+1),FALSE)} -> #N/A | D43: 0 | E43: 1
A44: qz2a | B44: 0 | C44: {=INDIRECT("table!R"&(MATCH(A44,table!$A$2:$A$17)+1)&"C"&(MATCH(BinaryAddition!B44,table!$B$1:$H$1,0)+1),FALSE)} -> q4,0,-1 | D44: 0 | E44: -1
A45: q0 | B45: 0 | C45: {=INDIRECT("table!R"&(MATCH(A45,table!$A$2:$A$17)+1)&"C"&(MATCH(BinaryAddition!B45,table!$B$1:$H$1,0)+1),FALSE)} -> #N/A | D45: 0 | E45: 1
...
